Workbook

Sheet Base de datos
A1: ID | B1: Proveedor | C1: Nombre ingrediente | D1: Formato compra | E1: Unidad de compra | F1: Precio formato compra | G1: Unidad Producto | H1: Precio Unidad Producto | I1: NOTAS
A2: 1 | B2: ADL | C2: Aceite Adl Alto Oleico 60% | D2: 25 | E2: Litro | F2: 45.8 | G2: Litro | H2: =F2/D2 -> 1.832
A3: =A2+1 -> 2 | B3: ADL | C3: Aceite de girasol Adl | D3: 25 | E3: Litro | F3: 37.95 | G3: Litro | H3: =F3/D3 -> 1.518
A4: =A3+1 -> 3 | B4: ADL | C4: ATUN EN ACEITE VEGETAL | D4: 1 | E4: Kg | F4: 5.75 | G4: Kg | H4: =F4/D4 -> 5.75
A5: =A4+1 -> 4 | B5: R2R | C5: BACON LONCHEADO 25 | D5: 1 | E5: Kg | F5: =5.07-(5.07*5%) -> 4.8165 | G5: Kg | H5: =F5/D5 -> 4.8165 | I5: %rappel aplicado
A6: =A5+1 -> 5 | B6: Neron | C6: bolsa lata delivery | D6: 250 | E6: Unidad | F6: 25 | G6: Unidad | H6: =F6/D6 -> 0.1
A7: =A6+1 -> 6 | B7: LUXBOX | C7: Bolsa personalizada | D7: 1 | E7: Unidad | F7: 0.243 | G7: Unidad | H7: =F7/D7 -> 0.243
A8: =A7+1 -> 7 | B8: Neron | C8: Bolsas AMERICANA GRANDE 25x15x43,5 | D8: 250 | E8: Unidad | F8: 31.15 | G8: Unidad | H8: =F8/D8 -> 0.1246
A9: =A8+1 -> 8 | B9: Neron | C9: Bolsas AMERICANA UNITARIA 18x34x11 | D9: 500 | E9: Unidad | F9: 37.97 | G9: Unidad | H9: =F9/D9 -> 0.07594
A10: =A9+1 -> 9 | B10: Neron | C10: CAJA BOX 780 | D10: 500 | E10: Kg | F10: 89.49 | H10: =F10/D10 -> 0.17898 | I10: la caja contiene 10 tiras de 50 unidades
A11: =A10+1 -> 10 | B11: Neron | C11: CAJA Burger blanca 234.18 | D11: 500 | E11: Kg | F11: 40.14 | H11: =F11/D11 -> 0.08028
A12: =A11+1 -> 11 | B12: LUXBOX | C12: Caja personalizada | D12: 1 | E12: Kg | F12: 0.261 | H12: =F12/D12 -> 0.261
A13: =A12+1 -> 12 | B13: BIENVENIDO CARNICAS | C13: CARNE B. | D13: 1 | E13: Kg | F13: =9/1.1 -> 8.1818182 | H13: =F13/D13 -> 8.1818182
A14: =A13+1 -> 13 | B14: MAKRO | C14: CEBOLLA CARAMELIZADA | D14: 0.9 | E14: Kg | F14: 5.62 | H14: =F14/D14 -> 6.2444444
A15: =A14+1 -> 14 | B15: BAREA | C15: CEBOLLA CRUJIENTE | D15: 0.5 | E15: Kg | F15: 3.47 | H15: =F15/D15 -> 6.94
A16: =A15+1 -> 15 | B16: F.CUEVAS | C16: CEBOLLA DULCE BLANCA | E16: Kg | H16: =F16/D16 -> #DIV/0!
A17: =A16+1 -> 16 | B17: MERCA | C17: CEBOLLA DULCE BLANCA | E17: Kg | H17: =F17/D17 -> #DIV/0!
A18: =A17+1 -> 17 | B18: F.CUEVAS | C18: CEBOLLA MORADA | E18: Kg | H18: =F18/D18 -> #DIV/0!
A19: =A18+1 -> 18 | B19: MERCA | C19: CEBOLLA MORADA | E19: Kg | H19: =F19/D19 -> #DIV/0!
A20: =A19+1 -> 19 | B20: R2R | C20: Chedar LONCHA R2R | D20: 8 | E20: Kg | F20: 80 | H20: =F20/D20 -> 10 | I20: no usado
A21: =A20+1 -> 20 | B21: SOLLERO | C21: CHEDDAR LIQUIDO SOLLERO | D21: 3 | E21: Kg | F21: 18.05 | H21: =F21/D21 -> 6.0166667
A22: =A21+1 -> 21 | B22: LA FUENTE | C22: CHEDDAR LONCHA LA FUENTE | D22: 1 | E22: Kg | F22: 8.56 | H22: =F22/D22 -> 8.56
A23: =A22+1 -> 22 | B23: LA FUENTE | C23: GOUDA LONCHA LA FUENTE | D23: 1 | F23: 7.11 | H23: =F23/D23 -> 7.11
A24: =A23+1 -> 23 | B24: LA FUENTE | C24: CHEDDAR SALSA LA FUENTE | D24: 3 | E24: Kg | F24: 13.17 | H24: =F24/D24 -> 4.39
A25: =A24+1 -> 24 | B25: SOLLERO | C25: CHEDDAR SOLLERO 25 | D25: 1 | E25: Kg | F25: 8.56 | H25: =F25/D25 -> 8.56
A26: =A25+1 -> 25 | B26: LAFUENTE | C26: RULO DE CABRA ORIGINAL LA FUENTE | D26: 1 | F26: 11.9 | H26: =F26/D26 -> 11.9
A27: =A26+1 -> 26 | B27: LAFUENTE | C27: RULO MEZCLA MADURADO LAFUENTE | D27: 1 | F27: 7.99 | H27: =F27/D27 -> 7.99
A28: =A27+1 -> 27 | B28: LAFUENTE | C28: CHEDDAR LONCHA ROJO LAFUENTE | D28: 1 | F28: 7.55 | H28: =F28/D28 -> 7.55
A29: =A28+1 -> 28 | B29: RAULFONT | C29: ENVASE BURG. SOFI | D29: 20000 | E29: Unidad | F29: =1746*2 -> 3492 | G29: Unidad | H29: =F29/D29 -> 0.1746
A30: =A29+1 -> 29 | B30: Neron | C30: ENVASE SERRANO IP10 .25 | D30: 50 | E30: Unidad | F30: 9.73 | G30: Unidad | H30: =F30/D30 -> 0.1946
A31: =A30+1 -> 30 | B31: ESPECIAS GRANADO | C31: ESPECIAS GRANADO POLLO ASADO | D31: 1 | E31: Kg | F31: 7 | H31: =F31/D31 -> 7
A32: =A31+1 -> 31 | B32: R2R | C32: FRANKFURT | D32: 15 | E32: Unidad | F32: =11.25-(11.25*5%) -> 10.6875 | H32: =F32/D32 -> 0.7125 | I32: % rappel aplicado
A33: =A32+1 -> 32 | B33: GRANJA S.A. | C33: CLARA LIQUIDA GRANJA | D33: 1 | F33: 2.5 | H33: =F33/D33 -> 2.5
A34: =A33+1 -> 33 | B34: Neron | C34: CAJA BOX 780 NEGRA OFERTA | D34: 500 | E34: Kg | F34: 70 | H34: =F34/D34 -> 0.14 | I34: la caja contiene 10 tiras de 50 unidades, OFERTA LIMITADA
A35: =A34+1 -> 34 | B35: GRANJA S.A. | C35: HUEVO LÍQUIDO GRANJA | D35: 1 | E35: Litro | F35: 3.75 | G35: Litro | H35: =F35/D35 -> 3.75
A36: =A35+1 -> 35 | B36: GRANJA S.A. | C36: HUEVO CASCARA | D36: 20 | E36: Unidad | F36: 2.9 | H36: =F36/D36 -> 0.145
A37: =A36+1 -> 36 | B37: R2R | C37: JALAPEÑOS | D37: 1 | E37: Kg | F37: 1.1 | H37: =F37/D37 -> 1.1
A38: =A37+1 -> 37 | B38: BAREA | C38: JAMON LONCHEADO CUMBRE IB. | D38: 1 | E38: Kg | F38: 7 | G38: Kg | H38: =F38/D38 -> 7
A39: =A38+1 -> 38 | B39: AVINATUR | C39: LAGRIMITAS | D39: 1 | E39: Kg | F39: 6 | H39: =F39/D39 -> 6
A40: =A39+1 -> 39 | B40: F.CUEVAS | C40: LECHUGA LOLLO CUEVAS | D40: 1 | E40: Kg | F40: 1.04 | H40: =F40/D40 -> 1.04
...

Sheet RESUMEN DE COSTES
I1: =SUM(I3:I59) -> 7524
A2: Familia | B2: Producto | C2: Coste € | D2: PVP sin IVA | E2: PVP Actual | F2: MARGEN € | G2: MARGEN % | H2: Coste % | I2: Unidades Vendidas | J2: Peso venta %
A3: Bocadillos | B3: =BOCATAS!D2 -> SIMPLE DE POLLO | C3: =BOCATAS!L6 -> 1.4018182 | D3: =BOCATAS!L8 -> 3.6363636 | E3: =D3*1.1 -> 4 | F3: =D3-C3 -> 2.2345455 | G3: =BOCATAS!L11 -> 61.45 | H3: =BOCATAS!L10 -> 38.55 | I3: 163 | J3: =I3/SUM($I$3:I201)*100 -> 2.1664009
A4: Bocadillos | B4: SIMPLE ASADO | C4: =BOCATAS!L34 -> 1.3407028 | D4: =BOCATAS!L36 -> 5 | E4: =D4*1.1 -> 5.5 | F4: =D4-C4 -> 3.6592972 | G4: =100-H4 -> 73.185944 | H4: =C4/D4*100 -> 26.814056 | I4: 33 | J4: =I4/SUM($I$3:I202)*100 -> 0.43859649
A5: Bocadillos | B5: SIMPLE EMPANADO | C5: =BOCATAS!L20 -> 1.3413182 | D5: =BOCATAS!L22 -> 4.5454545 | E5: =D5*1.1 -> 5 | F5: =D5-C5 -> 3.2041364 | G5: =100-H5 -> 70.491 | H5: =C5/D5*100 -> 29.509 | I5: 31 | J5: =I5/SUM($I$3:I203)*100 -> 0.41201489
A6: Bocadillos | B6: SIMPLE SOLOMILO | C6: =BOCATAS!L48 -> 1.2743182 | D6: =BOCATAS!L50 -> 4.5454545 | E6: =D6*1.1 -> 5 | F6: =D6-C6 -> 3.2711364 | G6: =100-H6 -> 71.965 | H6: =C6/D6*100 -> 28.035 | I6: 19 | J6: =I6/SUM($I$3:I204)*100 -> 0.25252525
A7: Bocadillos | B7: VEGETAL POLLO | C7: =BOCATAS!L63 -> 1.3687182 | D7: =BOCATAS!L65 -> 4.5454545 | E7: =D7*1.1 -> 5 | F7: =D7-C7 -> 3.1767364 | G7: =100-H7 -> 69.8882 | H7: =C7/D7*100 -> 30.1118 | I7: 218 | J7: =I7/SUM($I$3:I205)*100 -> 2.897395
A8: Bocadillos | B8: VEGETAL POLLO ASADO | C8: =BOCATAS!L95 -> 1.3691028 | D8: =BOCATAS!L97 -> 5.9090909 | E8: =D8*1.1 -> 6.5 | F8: =D8-C8 -> 4.5399881 | G8: =100-H8 -> 76.830568 | H8: =C8/D8*100 -> 23.169432 | I8: 173 | J8: =I8/SUM($I$3:I206)*100 -> 2.2993089
A9: Bocadillos | B9: VEGETAL EMPANADO | C9: =BOCATAS!L113 -> 1.3137182 | D9: =BOCATAS!L115 -> 4.5454545 | E9: =D9*1.1 -> 5 | F9: =D9-C9 -> 3.2317364 | G9: =100-H9 -> 71.0982 | H9: =C9/D9*100 -> 28.9018 | I9: 25 | J9: =I9/SUM($I$3:I207)*100 -> 0.33227007
A10: Bocadillos | B10: VEGETAL ATUN | C10: =BOCATAS!L79 -> 1.3287182 | D10: =BOCATAS!L81 -> 4.5454545 | E10: =D10*1.1 -> 5 | F10: =D10-C10 -> 3.2167364 | G10: =100-H10 -> 70.7682 | H10: =C10/D10*100 -> 29.2318 | I10: 35 | J10: =I10/SUM($I$3:I208)*100 -> 0.4651781
A11: Bocadillos | B11: BARBARA | C11: =BOCATAS!L131 -> 1.7153182 | D11: =BOCATAS!L133 -> 4.5454545 | E11: =D11*1.1 -> 5 | F11: =D11-C11 -> 2.8301364 | G11: =100-H11 -> 62.263 | H11: =C11/D11*100 -> 37.737 | I11: 249 | J11: =I11/SUM($I$3:I209)*100 -> 3.3094099
A12: Bocadillos | B12: CRISTIAN | C12: =BOCATAS!L147 -> 1.5238482 | D12: =BOCATAS!L149 -> 6.3636364 | E12: =D12*1.1 -> 7 | F12: =D12-C12 -> 4.8397882 | G12: =100-H12 -> 76.053814 | H12: =C12/D12*100 -> 23.946186 | I12: 188 | J12: =I12/SUM($I$3:I210)*100 -> 2.4986709
A13: Bocadillos | B13: JAKINIÑO | C13: =BOCATAS!L185 -> 1.8190482 | D13: =BOCATAS!L187 -> 7.2727273 | E13: =D13*1.1 -> 8 | F13: =D13-C13 -> 5.4536791 | G13: =100-H13 -> 74.988088 | H13: =C13/D13*100 -> 25.011913 | I13: 374 | J13: =I13/SUM($I$3:I211)*100 -> 4.9707602
A14: Bocadillos | B14: GUARRITO | C14: =BOCATAS!L166 -> 1.5106482 | D14: =BOCATAS!L168 -> 6.3636364 | E14: =D14*1.1 -> 7 | F14: =D14-C14 -> 4.8529882 | G14: =100-H14 -> 76.261243 | H14: =C14/D14*100 -> 23.738757 | I14: 197 | J14: =I14/SUM($I$3:I212)*100 -> 2.6182881
A16: SERRANITOS | B16: SERRANO EMPANADO | C16: =SERRANOS!L34 -> 1.5666182 | D16: =SERRANOS!L36 -> 5.9090909 | E16: =D16*1.1 -> 6.5 | F16: =D16-C16 -> 4.3424727 | G16: =100-H16 -> 73.488 | H16: =C16/D16*100 -> 26.512 | I16: 183 | J16: =I16/SUM($I$3:I214)*100 -> 2.4322169
A17: SERRANITOS | B17: SERRANO POLLO | C17: =SERRANOS!L6 -> 1.6271182 | D17: =SERRANOS!L8 -> 5.4545455 | E17: =D17*1.1 -> 6 | F17: =D17-C17 -> 3.8274273 | G17: =100-H17 -> 70.1695 | H17: =C17/D17*100 -> 29.8305 | I17: 1105 | J17: =I17/SUM($I$3:I215)*100 -> 14.686337
A18: SERRANITOS | B18: SERRANO POLLO ASADO | C18: =SERRANOS!L63 -> 1.5660028 | D18: =SERRANOS!L65 -> 5.9090909 | E18: =D18*1.1 -> 6.5 | F18: =D18-C18 -> 4.3430881 | G18: =100-H18 -> 73.498414 | H18: =C18/D18*100 -> 26.501586 | I18: 357 | J18: =I18/SUM($I$3:I216)*100 -> 4.7448166
A19: SERRANITOS | B19: SERRANO SOLOMILLO | C19: =SERRANOS!L92 -> 1.4996182 | D19: =SERRANOS!L94 -> 6.3636364 | E19: =D19*1.1 -> 7 | F19: =D19-C19 -> 4.8640182 | G19: =100-H19 -> 76.434571 | H19: =C19/D19*100 -> 23.565429 | I19: 270 | J19: =I19/SUM($I$3:I217)*100 -> 3.5885167
A20: SERRANITOS | B20: SERRANO PULLED PORK | C20: =SERRANOS!L121 -> 1.7827765 | D20: =SERRANOS!L123 -> 7.2727273 | E20: =D20*1.1 -> 8 | F20: =D20-C20 -> 5.4899508 | G20: =100-H20 -> 75.486823 | H20: =C20/D20*100 -> 24.513177 | J20: =I20/SUM($I$3:I218)*100 -> 0
A22: BRIOCHES | B22: XMAS CHIKEN | C22: ='BRIOCH-SUBS'!L177 -> 2.0977582 | D22: ='BRIOCH-SUBS'!L179 -> 9 | E22: =D22*1.1 -> 9.9 | F22: =D22-C22 -> 6.9022418 | G22: =100-H22 -> 76.691575 | H22: =C22/D22*100 -> 23.308425
A23: BRIOCHES | B23: CESAR BRIOCHE | C23: ='BRIOCH-SUBS'!L149 -> 1.98895 | D23: ='BRIOCH-SUBS'!L151 -> 7.7272727 | E23: =D23*1.1 -> 8.5 | F23: =D23-C23 -> 5.7383227 | G23: =100-H23 -> 74.260647 | H23: =C23/D23*100 -> 25.739353 | I23: 15 | J23: =I23/SUM($I$3:I221)*100 -> 0.19936204
A24: BRIOCHES | B24: GYPSY | C24: ='BRIOCH-SUBS'!L64 -> 1.9596667 | D24: ='BRIOCH-SUBS'!L66 -> 7.2727273 | E24: =D24*1.1 -> 8 | F24: =D24-C24 -> 5.3130606 | G24: =100-H24 -> 73.054583 | H24: =C24/D24*100 -> 26.945417 | I24: 71 | J24: =I24/SUM($I$3:I222)*100 -> 0.943647
A25: BRIOCHES | B25: CHICKEN FRIED | C25: ='BRIOCH-SUBS'!L6 -> 1.9732002 | D25: ='BRIOCH-SUBS'!L8 -> 7.2727273 | E25: =D25*1.1 -> 8 | F25: =D25-C25 -> 5.2995271 | G25: =100-H25 -> 72.868498 | H25: =C25/D25*100 -> 27.131502 | I25: 210 | J25: =I25/SUM($I$3:I223)*100 -> 2.7910686
A26: BRIOCHES | B26: CHEESE STEAK | C26: ='BRIOCH-SUBS'!L35 -> 2.3676979 | D26: ='BRIOCH-SUBS'!L37 -> 7.2727273 | E26: =D26*1.1 -> 8 | F26: =D26-C26 -> 4.9050294 | G26: =100-H26 -> 67.444154 | H26: =C26/D26*100 -> 32.555846 | J26: =I26/SUM($I$3:I224)*100 -> 0
A27: BRIOCHES | B27: SMASH SERRANO | C27: ='BRIOCH-SUBS'!L93 -> 1.9800455 | D27: ='BRIOCH-SUBS'!L95 -> 7.2727273 | E27: =D27*1.1 -> 8 | F27: =D27-C27 -> 5.2926818 | G27: =100-H27 -> 72.774375 | H27: =C27/D27*100 -> 27.225625 | I27: 144 | J27: =I27/SUM($I$3:I225)*100 -> 1.9138756
A30: BURGER | B30: CRUJIPOLLO BBQ | C30: =BURGERS!L239 -> 1.8604959 | D30: =BURGERS!L241 -> 7.2727273 | E30: =D30*1.1 -> 8 | F30: =D30-C30 -> 5.4122314 | G30: =100-H30 -> 74.418182 | H30: =C30/D30*100 -> 25.581818 | I30: 131 | J30: =I30/SUM($I$3:I228)*100 -> 1.7410952
A31: BURGER | B31: CRUJIPOLLO ORIGINAL | C31: =BURGERS!L269 -> 1.5300542 | D31: =BURGERS!L271 -> 6.3636364 | E31: =D31*1.1 -> 7 | F31: =D31-C31 -> 4.8335822 | G31: =100-H31 -> 75.956292 | H31: =C31/D31*100 -> 24.043708 | I31: 98 | J31: =I31/SUM($I$3:I229)*100 -> 1.3024987
A32: BURGER | B32: MAKA | C32: =BURGERS!L151 -> 2.2052973 | D32: =BURGERS!L153 -> 9 | E32: =D32*1.1 -> 9.9 | F32: =D32-C32 -> 6.7947027 | G32: =100-H32 -> 75.496696 | H32: =C32/D32*100 -> 24.503304 | I32: 210 | J32: =I32/SUM($I$3:I230)*100 -> 2.7910686
A33: BURGER | B33: BICHOTA | C33: =BURGERS!L180 -> 2.1501303 | D33: =BURGERS!L182 -> 9.0909091 | E33: =D33*1.1 -> 10 | F33: =D33-C33 -> 6.9407788 | G33: =100-H33 -> 76.348567 | H33: =C33/D33*100 -> 23.651433 | I33: 532 | J33: =I33/SUM($I$3:I231)*100 -> 7.0707071
A34: BURGER | B34: DADDY | C34: =BURGERS!L209 -> 2.5895738 | D34: =BURGERS!L211 -> 10 | E34: =D34*1.1 -> 11 | F34: =D34-C34 -> 7.4104262 | G34: =100-H34 -> 74.104262 | H34: =C34/D34*100 -> 25.895738 | J34: =I34/SUM($I$3:I232)*100 -> 0
A35: BURGER | B35: DOBLE QUESOS | C35: =BURGERS!L6 -> 2.1871023 | D35: =BURGERS!L8 -> 7.2727273 | E35: =D35*1.1 -> 8 | F35: =D35-C35 -> 5.0856249 | G35: =100-H35 -> 69.927343 | H35: =C35/D35*100 -> 30.072657 | I35: 781 | J35: =I35/SUM($I$3:I233)*100 -> 10.380117
A36: BURGER | B36: CERO15 | C36: =BURGERS!L35 -> 2.3754736 | D36: =BURGERS!L37 -> 7.2727273 | E36: =D36*1.1 -> 8 | F36: =D36-C36 -> 4.8972537 | G36: =100-H36 -> 67.337238 | H36: =C36/D36*100 -> 32.662762 | I36: 525 | J36: =I36/SUM($I$3:I234)*100 -> 6.9776715
A37: BURGER | B37: KAROL | C37: =BURGERS!L122 -> 2.5701467 | D37: =BURGERS!L124 -> 7.2727273 | E37: =D37*1.1 -> 8 | F37: =D37-C37 -> 4.7025805 | G37: =100-H37 -> 64.660482 | H37: =C37/D37*100 -> 35.339518 | J37: =I37/SUM($I$3:I235)*100 -> 0
A38: BURGER | B38: BARRIERA | C38: =BURGERS!L93 -> 2.6506748 | D38: =BURGERS!L95 -> 6.3636364 | E38: =D38*1.1 -> 7 | F38: =D38-C38 -> 3.7129615 | G38: =100-H38 -> 58.346539 | H38: =C38/D38*100 -> 41.653461 | I38: 383 | J38: =I38/SUM($I$3:I236)*100 -> 5.0903775
A39: BURGER | B39: CALLEJERA | C39: =BURGERS!L64 -> 2.4731124 | D39: =BURGERS!L66 -> 9 | E39: =D39*1.1 -> 9.9 | F39: =D39-C39 -> 6.5268876 | G39: =100-H39 -> 72.520973 | H39: =C39/D39*100 -> 27.479027 | I39: 0 | J39: =I39/SUM($I$3:I237)*100 -> 0
A41: ENTRANTES | B41: BOX ALITAS | C41: =ENTRANTES!L34 -> 2.4242067 | D41: =ENTRANTES!L36 -> 5.4545455 | E41: =D41*1.1 -> 6 | F41: =D41-C41 -> 3.0303387 | G41: =100-H41 -> 55.55621 | H41: =C41/D41*100 -> 44.44379 | I41: 85 | J41: =I41/SUM($I$3:I239)*100 -> 1.1297182
A42: ENTRANTES | B42: BOX LAGRIMITAS | C42: =ENTRANTES!L90 -> 1.5589067 | D42: =ENTRANTES!L92 -> 5.4545455 | E42: =D42*1.1 -> 6 | F42: =D42-C42 -> 3.8956387 | G42: =100-H42 -> 71.420044 | H42: =C42/D42*100 -> 28.579956 | I42: 113 | J42: =I42/SUM($I$3:I240)*100 -> 1.5018607
A43: ENTRANTES | B43: BOX NUGGETS | C43: =ENTRANTES!L6 -> 1.8325067 | D43: =ENTRANTES!L8 -> 5.4545455 | E43: =D43*1.1 -> 6 | F43: =D43-C43 -> 3.6220387 | G43: =100-H43 -> 66.404044 | H43: =C43/D43*100 -> 33.595956 | I43: 98 | J43: =I43/SUM($I$3:I241)*100 -> 1.3024987
A44: ENTRANTES | B44: BOX PATATAS | C44: =ENTRANTES!L118 -> 0.91663342 | D44: =ENTRANTES!L120 -> 4.5454545 | E44: =D44*1.1 -> 5 | F44: =D44-C44 -> 3.6288211 | G44: =100-H44 -> 79.834065 | H44: =C44/D44*100 -> 20.165935 | I44: 164 | J44: =I44/SUM($I$3:I242)*100 -> 2.1796917
A45: ENTRANTES | B45: BOX PAPAS PULLED PORK | C45: =ENTRANTES!L174 -> 1.3761221 | D45: =ENTRANTES!L176 -> 6.3636364 | E45: =D45*1.1 -> 7 | F45: =D45-C45 -> 4.9875142 | G45: =100-H45 -> 78.375224 | H45: =C45/D45*100 -> 21.624776 | I45: 91 | J45: =I45/SUM($I$3:I243)*100 -> 1.2094631
...

Sheet UPSMENUS
L1: 1.5
A2: Familia | B2: Producto | C2: Coste € | D2: PVP sin IVA | E2: PVP Actual | F2: MARGEN € | G2: MARGEN % | H2: Coste % | I2: TARROS | J2: BEBIDAS | K2: COSTE T. | L2: PVP MENU X | M2: PVP sin Iva. | N2: PVP + MENU X | O2: MARGEN € | P2: MARGEN % | Q2: Coste % | R2: DIF. MARGEN | S2: DIF. PVP
A3: Bocadillos | B3: =BOCATAS!D2 -> SIMPLE DE POLLO | C3: =BOCATAS!L6 -> 1.4018182 | D3: =BOCATAS!L8 -> 3.6363636 | E3: =D3*1.1 -> 4 | F3: =D3-C3 -> 2.2345455 | G3: =100-H3 -> 61.45 | H3: =C3/D3*100 -> 38.55 | I3: 0.19187671 | J3: 0.61375 | K3: =I3+J3+C3 -> 2.2074449 | L3: =$L$1/1.1 -> 1.3636364 | M3: =D3+L3 -> 5 | N3: =E3+(L3*1.1) -> 5.5 | O3: =M3-K3 -> 2.7925551 | P3: =100-Q3 -> 55.851102 | Q3: =K3/M3*100 -> 44.148898 | R3: =P3-G3 -> -5.5988978 | S3: =O3-F3 -> 0.55800965 | U3: UBER | V3: SERRANITOS & BAGUETTES by SOFI | W3: 622 | X3: 5543.3
A4: Bocadillos | B4: SIMPLE ASADO | C4: =BOCATAS!L34 -> 1.3407028 | D4: =BOCATAS!L36 -> 5 | E4: =D4*1.1 -> 5.5 | F4: =D4-C4 -> 3.6592972 | G4: =100-H4 -> 73.185944 | H4: =C4/D4*100 -> 26.814056 | I4: 0.19187671 | J4: 0.61375 | K4: =I4+J4+C4 -> 2.1463295 | L4: =$L$1/1.1 -> 1.3636364 | M4: =D4+1.36 -> 6.36 | N4: =E4+(L4*1.1) -> 7 | O4: =M4-K4 -> 4.2136705 | P4: =100-Q4 -> 66.252681 | Q4: =K4/M4*100 -> 33.747319 | R4: =P4-G4 -> -6.9332634 | S4: =O4-F4 -> 0.55437329 | U4: UBER | V4: BURGERS | W4: 426 | X4: 5106.7
A5: Bocadillos | B5: SIMPLE EMPANADO | C5: =BOCATAS!L20 -> 1.3413182 | D5: =BOCATAS!L22 -> 4.5454545 | E5: =D5*1.1 -> 5 | F5: =D5-C5 -> 3.2041364 | G5: =100-H5 -> 70.491 | H5: =C5/D5*100 -> 29.509 | I5: 0.19187671 | J5: 0.61375 | K5: =I5+J5+C5 -> 2.1469449 | L5: =$L$1/1.1 -> 1.3636364 | M5: =D5+1.36 -> 5.9054545 | N5: =E5+(L5*1.1) -> 6.5 | O5: =M5-K5 -> 3.7585097 | P5: =100-Q5 -> 63.644714 | Q5: =K5/M5*100 -> 36.355286 | R5: =P5-G5 -> -6.846286 | S5: =O5-F5 -> 0.55437329 | U5: UBER | V5: NUEVOS SUB´s (BRIOCHES) | W5: 315 | X5: 3454.2
A6: Bocadillos | B6: SIMPLE SOLOMILO | C6: =BOCATAS!L48 -> 1.2743182 | D6: =BOCATAS!L50 -> 4.5454545 | E6: =D6*1.1 -> 5 | F6: =D6-C6 -> 3.2711364 | G6: =100-H6 -> 71.965 | H6: =C6/D6*100 -> 28.035 | I6: 0.19187671 | J6: 0.61375 | K6: =I6+J6+C6 -> 2.0799449 | L6: =$L$1/1.1 -> 1.3636364 | M6: =D6+1.36 -> 5.9054545 | N6: =E6+(L6*1.1) -> 6.5 | O6: =M6-K6 -> 3.8255097 | P6: =100-Q6 -> 64.779258 | Q6: =K6/M6*100 -> 35.220742 | R6: =P6-G6 -> -7.1857417 | S6: =O6-F6 -> 0.55437329 | U6: UBER | V6: CAMPEONATO DE BOCATAS DE ESPAÑA | W6: 98 | X6: 1322.6
A7: Bocadillos | B7: VEGETAL POLLO | C7: =BOCATAS!L63 -> 1.3687182 | D7: =BOCATAS!L65 -> 4.5454545 | E7: =D7*1.1 -> 5 | F7: =D7-C7 -> 3.1767364 | G7: =100-H7 -> 69.8882 | H7: =C7/D7*100 -> 30.1118 | I7: 0.19187671 | J7: 0.61375 | K7: =I7+J7+C7 -> 2.1743449 | L7: =$L$1/1.1 -> 1.3636364 | M7: =D7+1.36 -> 5.9054545 | N7: =E7+(L7*1.1) -> 6.5 | O7: =M7-K7 -> 3.7311097 | P7: =100-Q7 -> 63.180736 | Q7: =K7/M7*100 -> 36.819264 | R7: =P7-G7 -> -6.7074639 | S7: =O7-F7 -> 0.55437329 | X7: SIN MENU | Y7: CON MENU | Z7: DIFERENCIA | AA7: MARGEN | AB7: DIF. MARGEN
A8: Bocadillos | B8: VEGETAL POLLO ASADO | C8: =BOCATAS!L95 -> 1.3691028 | D8: =BOCATAS!L97 -> 5.9090909 | E8: =D8*1.1 -> 6.5 | F8: =D8-C8 -> 4.5399881 | G8: =100-H8 -> 76.830568 | H8: =C8/D8*100 -> 23.169432 | I8: 0.19187671 | J8: 0.61375 | K8: =I8+J8+C8 -> 2.1747295 | L8: =$L$1/1.1 -> 1.3636364 | M8: =D8+1.36 -> 7.2690909 | N8: =E8+(L8*1.1) -> 8 | O8: =M8-K8 -> 5.0943614 | P8: =100-Q8 -> 70.082511 | Q8: =K8/M8*100 -> 29.917489 | R8: =P8-G8 -> -6.7480575 | S8: =O8-F8 -> 0.55437329 | U8: LOCAL | V8: Burgers | W8: 1361 | X8: 11905.2 | Y8: =X8+(W8*1.5) -> 13946.7 | Z8: =Y8-X8 -> 2041.5 | AA8: =X8+(W8*0.55) -> 12653.75 | AB8: =AA8-X8 -> 748.55
A9: Bocadillos | B9: VEGETAL EMPANADO | C9: =BOCATAS!L113 -> 1.3137182 | D9: =BOCATAS!L115 -> 4.5454545 | E9: =D9*1.1 -> 5 | F9: =D9-C9 -> 3.2317364 | G9: =100-H9 -> 71.0982 | H9: =C9/D9*100 -> 28.9018 | I9: 0.19187671 | J9: 0.61375 | K9: =I9+J9+C9 -> 2.1193449 | L9: =$L$1/1.1 -> 1.3636364 | M9: =D9+1.36 -> 5.9054545 | N9: =E9+(L9*1.1) -> 6.5 | O9: =M9-K9 -> 3.7861097 | P9: =100-Q9 -> 64.112078 | Q9: =K9/M9*100 -> 35.887922 | R9: =P9-G9 -> -6.9861215 | S9: =O9-F9 -> 0.55437329 | U9: LOCAL | V9: Serranitos | W9: 787 | X9: 5055.5 | Y9: =X9+(W9*1.5) -> 6236 | Z9: =Y9-X9 -> 1180.5 | AA9: =X9+(W9*0.55) -> 5488.35 | AB9: =AA9-X9 -> 432.85
A10: Bocadillos | B10: VEGETAL ATUN | C10: =BOCATAS!L79 -> 1.3287182 | D10: =BOCATAS!L81 -> 4.5454545 | E10: =D10*1.1 -> 5 | F10: =D10-C10 -> 3.2167364 | G10: =100-H10 -> 70.7682 | H10: =C10/D10*100 -> 29.2318 | I10: 0.19187671 | J10: 0.61375 | K10: =I10+J10+C10 -> 2.1343449 | L10: =$L$1/1.1 -> 1.3636364 | M10: =D10+1.36 -> 5.9054545 | N10: =E10+(L10*1.1) -> 6.5 | O10: =M10-K10 -> 3.7711097 | P10: =100-Q10 -> 63.858076 | Q10: =K10/M10*100 -> 36.141924 | R10: =P10-G10 -> -6.910124 | S10: =O10-F10 -> 0.55437329 | U10: LOCAL | V10: Brioches | W10: 610 | X10: 4788.4 | Y10: =X10+(W10*1.5) -> 5703.4 | Z10: =Y10-X10 -> 915 | AA10: =X10+(W10*0.55) -> 5123.9 | AB10: =AA10-X10 -> 335.5
A11: Bocadillos | B11: BARBARA | C11: =BOCATAS!L131 -> 1.7153182 | D11: =BOCATAS!L133 -> 4.5454545 | E11: =D11*1.1 -> 5 | F11: =D11-C11 -> 2.8301364 | G11: =100-H11 -> 62.263 | H11: =C11/D11*100 -> 37.737 | I11: 0.19187671 | J11: 0.61375 | K11: =I11+J11+C11 -> 2.5209449 | L11: =$L$1/1.1 -> 1.3636364 | M11: =D11+1.36 -> 5.9054545 | N11: =E11+(L11*1.1) -> 6.5 | O11: =M11-K11 -> 3.3845097 | P11: =100-Q11 -> 57.311586 | Q11: =K11/M11*100 -> 42.688414 | R11: =P11-G11 -> -4.9514141 | S11: =O11-F11 -> 0.55437329 | U11: LOCAL | V11: Bocatas | W11: 484 | X11: 3326.8 | Y11: =X11+(W11*1.5) -> 4052.8 | Z11: =Y11-X11 -> 726 | AA11: =X11+(W11*0.55) -> 3593 | AB11: =AA11-X11 -> 266.2
A12: Bocadillos | B12: CRISTIAN | C12: =BOCATAS!L147 -> 1.5238482 | D12: =BOCATAS!L149 -> 6.3636364 | E12: =D12*1.1 -> 7 | F12: =D12-C12 -> 4.8397882 | G12: =100-H12 -> 76.053814 | H12: =C12/D12*100 -> 23.946186 | I12: 0.19187671 | J12: 0.61375 | K12: =I12+J12+C12 -> 2.3294749 | L12: =$L$1/1.1 -> 1.3636364 | M12: =D12+1.36 -> 7.7236364 | N12: =E12+(L12*1.1) -> 8.5 | O12: =M12-K12 -> 5.3941615 | P12: =100-Q12 -> 69.839661 | Q12: =K12/M12*100 -> 30.160339 | R12: =P12-G12 -> -6.2141531 | S12: =O12-F12 -> 0.55437329 | U12: LOCAL | V12: Bocatas Vegetales | W12: 174 | X12: 939 | Y12: =X12+(W12*1.5) -> 1200 | Z12: =Y12-X12 -> 261 | AA12: =X12+(W12*0.55) -> 1034.7 | AB12: =AA12-X12 -> 95.7
A13: Bocadillos | B13: JAKINIÑO | C13: =BOCATAS!L185 -> 1.8190482 | D13: =BOCATAS!L187 -> 7.2727273 | E13: =D13*1.1 -> 8 | F13: =D13-C13 -> 5.4536791 | G13: =100-H13 -> 74.988088 | H13: =C13/D13*100 -> 25.011913 | I13: 0.19187671 | J13: 0.61375 | K13: =I13+J13+C13 -> 2.6246749 | L13: =$L$1/1.1 -> 1.3636364 | M13: =D13+1.36 -> 8.6327273 | N13: =E13+(L13*1.1) -> 9.5 | O13: =M13-K13 -> 6.0080524 | P13: =100-Q13 -> 69.596226 | Q13: =K13/M13*100 -> 30.403774 | R13: =P13-G13 -> -5.3918615 | S13: =O13-F13 -> 0.55437329 | U13: LOCAL | V13: BOCATAS SIMPLES | W13: 163 | X13: 791.5 | Y13: =X13+(W13*1.5) -> 1036 | Z13: =Y13-X13 -> 244.5 | AA13: =X13+(W13*0.55) -> 881.15 | AB13: =AA13-X13 -> 89.65
A14: Bocadillos | B14: GUARRITO | C14: =BOCATAS!L166 -> 1.5106482 | D14: =BOCATAS!L168 -> 6.3636364 | E14: =D14*1.1 -> 7 | F14: =D14-C14 -> 4.8529882 | G14: =100-H14 -> 76.261243 | H14: =C14/D14*100 -> 23.738757 | I14: 0.19187671 | J14: 0.61375 | K14: =I14+J14+C14 -> 2.3162749 | L14: =$L$1/1.1 -> 1.3636364 | M14: =D14+1.36 -> 7.7236364 | N14: =E14+(L14*1.1) -> 8.5 | O14: =M14-K14 -> 5.4073615 | P14: =100-Q14 -> 70.010565 | Q14: =K14/M14*100 -> 29.989435 | R14: =P14-G14 -> -6.2506777 | S14: =O14-F14 -> 0.55437329
A16: SERRANITOS | B16: SERRANO EMPANADO | C16: =SERRANOS!L34 -> 1.5666182 | D16: =SERRANOS!L36 -> 5.9090909 | E16: =D16*1.1 -> 6.5 | F16: =D16-C16 -> 4.3424727 | G16: =100-H16 -> 73.488 | H16: =C16/D16*100 -> 26.512 | I16: 0.19187671 | J16: 0.61375 | K16: =I16+J16+C16 -> 2.3722449 | L16: =$L$1/1.1 -> 1.3636364 | M16: =D16+1.36 -> 7.2690909 | N16: =E16+(L16*1.1) -> 8 | O16: =M16-K16 -> 4.896846 | P16: =100-Q16 -> 67.365315 | Q16: =K16/M16*100 -> 32.634685 | R16: =P16-G16 -> -6.1226846 | S16: =O16-F16 -> 0.55437329 | V16: TOTAL FACTURACION LOCAL | W16: =SUM(X8:X13) -> 26806.4
A17: SERRANITOS | B17: SERRANO POLLO | C17: =SERRANOS!L6 -> 1.6271182 | D17: =SERRANOS!L8 -> 5.4545455 | E17: =D17*1.1 -> 6 | F17: =D17-C17 -> 3.8274273 | G17: =100-H17 -> 70.1695 | H17: =C17/D17*100 -> 29.8305 | I17: 0.19187671 | J17: 0.61375 | K17: =I17+J17+C17 -> 2.4327449 | L17: =$L$1/1.1 -> 1.3636364 | M17: =D17+1.36 -> 6.8145455 | N17: =E17+(L17*1.1) -> 7.5 | O17: =M17-K17 -> 4.3818006 | P17: =100-Q17 -> 64.300702 | Q17: =K17/M17*100 -> 35.699298 | R17: =P17-G17 -> -5.868798 | S17: =O17-F17 -> 0.55437329 | V17: TOTAL FACT. MENU | W17: =SUM(Y8:Y13) -> 32174.9
A18: SERRANITOS | B18: SERRANO POLLO ASADO | C18: =SERRANOS!L63 -> 1.5660028 | D18: =SERRANOS!L65 -> 5.9090909 | E18: =D18*1.1 -> 6.5 | F18: =D18-C18 -> 4.3430881 | G18: =100-H18 -> 73.498414 | H18: =C18/D18*100 -> 26.501586 | I18: 0.19187671 | J18: 0.61375 | K18: =I18+J18+C18 -> 2.3716295 | L18: =$L$1/1.1 -> 1.3636364 | M18: =D18+1.36 -> 7.2690909 | N18: =E18+(L18*1.1) -> 8 | O18: =M18-K18 -> 4.8974614 | P18: =100-Q18 -> 67.373781 | Q18: =K18/M18*100 -> 32.626219 | R18: =P18-G18 -> -6.124633 | S18: =O18-F18 -> 0.55437329 | V18: DIFERENCIA | W18: =W17-W16 -> 5368.5
A19: SERRANITOS | B19: SERRANO SOLOMILLO | C19: =SERRANOS!L92 -> 1.4996182 | D19: =SERRANOS!L94 -> 6.3636364 | E19: =D19*1.1 -> 7 | F19: =D19-C19 -> 4.8640182 | G19: =100-H19 -> 76.434571 | H19: =C19/D19*100 -> 23.565429 | I19: 0.19187671 | J19: 0.61375 | K19: =I19+J19+C19 -> 2.3052449 | L19: =$L$1/1.1 -> 1.3636364 | M19: =D19+1.36 -> 7.7236364 | N19: =E19+(L19*1.1) -> 8.5 | O19: =M19-K19 -> 5.4183915 | P19: =100-Q19 -> 70.153374 | Q19: =K19/M19*100 -> 29.846626 | R19: =P19-G19 -> -6.2811979 | S19: =O19-F19 -> 0.55437329 | V19: DIFERENCIA MARGEN | W19: =SUM(AB8:AB13) -> 1968.45
A20: SERRANITOS | B20: SERRANO PULLED PORK | C20: =SERRANOS!L121 -> 1.7827765 | D20: =SERRANOS!L123 -> 7.2727273 | E20: =D20*1.1 -> 8 | F20: =D20-C20 -> 5.4899508 | G20: =100-H20 -> 75.486823 | H20: =C20/D20*100 -> 24.513177 | I20: 0.19187671 | J20: 0.61375 | K20: =I20+J20+C20 -> 2.5884032 | L20: =$L$1/1.1 -> 1.3636364 | M20: =D20+1.36 -> 8.6327273 | N20: =E20+(L20*1.1) -> 9.5 | O20: =M20-K20 -> 6.044324 | P20: =100-Q20 -> 70.016391 | Q20: =K20/M20*100 -> 29.983609 | R20: =P20-G20 -> -5.4704323 | S20: =O20-F20 -> 0.55437329
A22: BRIOCHES | B22: XMAS CHIKEN | C22: ='BRIOCH-SUBS'!L177 -> 2.0977582 | D22: ='BRIOCH-SUBS'!L179 -> 9 | E22: =D22*1.1 -> 9.9 | F22: =D22-C22 -> 6.9022418 | G22: =100-H22 -> 76.691575 | H22: =C22/D22*100 -> 23.308425 | I22: 0.19187671 | J22: 0.61375 | K22: =I22+J22+C22 -> 2.9033849 | L22: =$L$1/1.1 -> 1.3636364 | M22: =D22+1.36 -> 10.36 | N22: =E22+1.5 -> 11.4 | O22: =M22-K22 -> 7.4566151 | P22: =100-Q22 -> 71.975049 | Q22: =K22/M22*100 -> 28.024951 | R22: =P22-G22 -> -4.7165264 | S22: =O22-F22 -> 0.55437329
A23: BRIOCHES | B23: CESAR BRIOCHE | C23: ='BRIOCH-SUBS'!L149 -> 1.98895 | D23: ='BRIOCH-SUBS'!L151 -> 7.7272727 | E23: =D23*1.1 -> 8.5 | F23: =D23-C23 -> 5.7383227 | G23: =100-H23 -> 74.260647 | H23: =C23/D23*100 -> 25.739353 | I23: 0.19187671 | J23: 0.61375 | K23: =I23+J23+C23 -> 2.7945767 | L23: =$L$1/1.1 -> 1.3636364 | M23: =D23+1.36 -> 9.0872727 | N23: =E23+1.5 -> 10 | O23: =M23-K23 -> 6.292696 | P23: =100-Q23 -> 69.247355 | Q23: =K23/M23*100 -> 30.752645 | R23: =P23-G23 -> -5.0132919 | S23: =O23-F23 -> 0.55437329
A24: BRIOCHES | B24: GYPSY | C24: ='BRIOCH-SUBS'!L64 -> 1.9596667 | D24: ='BRIOCH-SUBS'!L66 -> 7.2727273 | E24: =D24*1.1 -> 8 | F24: =D24-C24 -> 5.3130606 | G24: =100-H24 -> 73.054583 | H24: =C24/D24*100 -> 26.945417 | I24: 0.19187671 | J24: 0.61375 | K24: =I24+J24+C24 -> 2.7652934 | L24: =$L$1/1.1 -> 1.3636364 | M24: =D24+1.36 -> 8.6327273 | N24: =E24+1.5 -> 9.5 | O24: =M24-K24 -> 5.8674339 | P24: =100-Q24 -> 67.967326 | Q24: =K24/M24*100 -> 32.032674 | R24: =P24-G24 -> -5.0872572 | S24: =O24-F24 -> 0.55437329
A25: BRIOCHES | B25: CHICKEN FRIED | C25: ='BRIOCH-SUBS'!L6 -> 1.9732002 | D25: ='BRIOCH-SUBS'!L8 -> 7.2727273 | E25: =D25*1.1 -> 8 | F25: =D25-C25 -> 5.2995271 | G25: =100-H25 -> 72.868498 | H25: =C25/D25*100 -> 27.131502 | I25: 0.19187671 | J25: 0.61375 | K25: =I25+J25+C25 -> 2.7788269 | L25: =$L$1/1.1 -> 1.3636364 | M25: =D25+1.36 -> 8.6327273 | N25: =E25+1.5 -> 9.5 | O25: =M25-K25 -> 5.8539004 | P25: =100-Q25 -> 67.810556 | Q25: =K25/M25*100 -> 32.189444 | R25: =P25-G25 -> -5.0579413 | S25: =O25-F25 -> 0.55437329
A26: BRIOCHES | B26: CHEESE STEAK | C26: ='BRIOCH-SUBS'!L35 -> 2.3676979 | D26: ='BRIOCH-SUBS'!L37 -> 7.2727273 | E26: =D26*1.1 -> 8 | F26: =D26-C26 -> 4.9050294 | G26: =100-H26 -> 67.444154 | H26: =C26/D26*100 -> 32.555846 | I26: 0.19187671 | J26: 0.61375 | K26: =I26+J26+C26 -> 3.1733246 | L26: =$L$1/1.1 -> 1.3636364 | M26: =D26+1.36 -> 8.6327273 | N26: =E26+1.5 -> 9.5 | O26: =M26-K26 -> 5.4594026 | P26: =100-Q26 -> 63.240764 | Q26: =K26/M26*100 -> 36.759236 | R26: =P26-G26 -> -4.2033901 | S26: =O26-F26 -> 0.55437329
A27: BRIOCHES | B27: SMASH SERRANO | C27: ='BRIOCH-SUBS'!L93 -> 1.9800455 | D27: ='BRIOCH-SUBS'!L95 -> 7.2727273 | E27: =D27*1.1 -> 8 | F27: =D27-C27 -> 5.2926818 | G27: =100-H27 -> 72.774375 | H27: =C27/D27*100 -> 27.225625 | I27: 0.19187671 | J27: 0.61375 | K27: =I27+J27+C27 -> 2.7856722 | L27: =$L$1/1.1 -> 1.3636364 | M27: =D27+1.36 -> 8.6327273 | N27: =E27+1.5 -> 9.5 | O27: =M27-K27 -> 5.8470551 | P27: =100-Q27 -> 67.731262 | Q27: =K27/M27*100 -> 32.268738 | R27: =P27-G27 -> -5.0431132 | S27: =O27-F27 -> 0.55437329
A30: BURGER | B30: CRUJIPOLLO BBQ | C30: =BURGERS!L239 -> 1.8604959 | D30: =BURGERS!L241 -> 7.2727273 | E30: =D30*1.1 -> 8 | F30: =D30-C30 -> 5.4122314 | G30: =100-H30 -> 74.418182 | H30: =C30/D30*100 -> 25.581818 | I30: 0.19187671 | J30: 0.61375 | K30: =I30+J30+C30 -> 2.6661226 | L30: =$L$1/1.1 -> 1.3636364 | M30: =D30+1.36 -> 8.6327273 | N30: =E30+1.5 -> 9.5 | O30: =M30-K30 -> 5.9666047 | P30: =100-Q30 -> 69.116103 | Q30: =K30/M30*100 -> 30.883897 | R30: =P30-G30 -> -5.3020786 | S30: =O30-F30 -> 0.55437329
A31: BURGER | B31: CRUJIPOLLO ORIGINAL | C31: =BURGERS!L269 -> 1.5300542 | D31: =BURGERS!L271 -> 6.3636364 | E31: =D31*1.1 -> 7 | F31: =D31-C31 -> 4.8335822 | G31: =100-H31 -> 75.956292 | H31: =C31/D31*100 -> 24.043708 | I31: 0.19187671 | J31: 0.61375 | K31: =I31+J31+C31 -> 2.3356809 | L31: =$L$1/1.1 -> 1.3636364 | M31: =D31+1.36 -> 7.7236364 | N31: =E31+1.5 -> 8.5 | O31: =M31-K31 -> 5.3879555 | P31: =100-Q31 -> 69.759311 | Q31: =K31/M31*100 -> 30.240689 | R31: =P31-G31 -> -6.196981 | S31: =O31-F31 -> 0.55437329
A32: BURGER | B32: MAKA | C32: =BURGERS!L151 -> 2.2052973 | D32: =BURGERS!L153 -> 9 | E32: =D32*1.1 -> 9.9 | F32: =D32-C32 -> 6.7947027 | G32: =100-H32 -> 75.496696 | H32: =C32/D32*100 -> 24.503304 | I32: 0.19187671 | J32: 0.61375 | K32: =I32+J32+C32 -> 3.0109241 | L32: =$L$1/1.1 -> 1.3636364 | M32: =D32+1.36 -> 10.36 | N32: =E32+1.5 -> 11.4 | O32: =M32-K32 -> 7.3490759 | P32: =100-Q32 -> 70.937026 | Q32: =K32/M32*100 -> 29.062974 | R32: =P32-G32 -> -4.5596697 | S32: =O32-F32 -> 0.55437329
A33: BURGER | B33: BICHOTA | C33: =BURGERS!L180 -> 2.1501303 | D33: =BURGERS!L182 -> 9.0909091 | E33: =D33*1.1 -> 10 | F33: =D33-C33 -> 6.9407788 | G33: =100-H33 -> 76.348567 | H33: =C33/D33*100 -> 23.651433 | I33: 0.19187671 | J33: 0.61375 | K33: =I33+J33+C33 -> 2.955757 | L33: =$L$1/1.1 -> 1.3636364 | M33: =D33+1.36 -> 10.450909 | N33: =E33+1.5 -> 11.5 | O33: =M33-K33 -> 7.4951521 | P33: =100-Q33 -> 71.717704 | Q33: =K33/M33*100 -> 28.282296 | R33: =P33-G33 -> -4.6308624 | S33: =O33-F33 -> 0.55437329
A34: BURGER | B34: DADDY | C34: =BURGERS!L209 -> 2.5895738 | D34: =BURGERS!L211 -> 10 | E34: =D34*1.1 -> 11 | F34: =D34-C34 -> 7.4104262 | G34: =100-H34 -> 74.104262 | H34: =C34/D34*100 -> 25.895738 | I34: 0.19187671 | J34: 0.61375 | K34: =I34+J34+C34 -> 3.3952005 | L34: =$L$1/1.1 -> 1.3636364 | M34: =D34+1.36 -> 11.36 | N34: =E34+1.5 -> 12.5 | O34: =M34-K34 -> 7.9647995 | P34: =100-Q34 -> 70.112671 | Q34: =K34/M34*100 -> 29.887329 | R34: =P34-G34 -> -3.9915904 | S34: =O34-F34 -> 0.55437329
A35: BURGER | B35: DOBLE QUESOS | C35: =BURGERS!L6 -> 2.1871023 | D35: =BURGERS!L8 -> 7.2727273 | E35: =D35*1.1 -> 8 | F35: =D35-C35 -> 5.0856249 | G35: =100-H35 -> 69.927343 | H35: =C35/D35*100 -> 30.072657 | I35: 0.19187671 | J35: 0.61375 | K35: =I35+J35+C35 -> 2.9927291 | L35: =$L$1/1.1 -> 1.3636364 | M35: =D35+1.36 -> 8.6327273 | N35: =E35+1.5 -> 9.5 | O35: =M35-K35 -> 5.6399982 | P35: =100-Q35 -> 65.332751 | Q35: =K35/M35*100 -> 34.667249 | R35: =P35-G35 -> -4.5945917 | S35: =O35-F35 -> 0.55437329
A36: BURGER | B36: CERO15 | C36: =BURGERS!L35 -> 2.3754736 | D36: =BURGERS!L37 -> 7.2727273 | E36: =D36*1.1 -> 8 | F36: =D36-C36 -> 4.8972537 | G36: =100-H36 -> 67.337238 | H36: =C36/D36*100 -> 32.662762 | I36: 0.19187671 | J36: 0.61375 | K36: =I36+J36+C36 -> 3.1811003 | L36: =$L$1/1.1 -> 1.3636364 | M36: =D36+1.36 -> 8.6327273 | N36: =E36+1.5 -> 9.5 | O36: =M36-K36 -> 5.451627 | P36: =100-Q36 -> 63.150691 | Q36: =K36/M36*100 -> 36.849309 | R36: =P36-G36 -> -4.1865466 | S36: =O36-F36 -> 0.55437329
A37: BURGER | B37: KAROL | C37: =BURGERS!L122 -> 2.5701467 | D37: =BURGERS!L124 -> 7.2727273 | E37: =D37*1.1 -> 8 | F37: =D37-C37 -> 4.7025805 | G37: =100-H37 -> 64.660482 | H37: =C37/D37*100 -> 35.339518 | I37: 0.19187671 | J37: 0.61375 | K37: =I37+J37+C37 -> 3.3757735 | L37: =$L$1/1.1 -> 1.3636364 | M37: =D37+1.36 -> 8.6327273 | N37: =E37+1.5 -> 9.5 | O37: =M37-K37 -> 5.2569538 | P37: =100-Q37 -> 60.895632 | Q37: =K37/M37*100 -> 39.104368 | R37: =P37-G37 -> -3.7648504 | S37: =O37-F37 -> 0.55437329
A38: BURGER | B38: BARRIERA | C38: =BURGERS!L93 -> 2.6506748 | D38: =BURGERS!L95 -> 6.3636364 | E38: =D38*1.1 -> 7 | F38: =D38-C38 -> 3.7129615 | G38: =100-H38 -> 58.346539 | H38: =C38/D38*100 -> 41.653461 | I38: 0.19187671 | J38: 0.61375 | K38: =I38+J38+C38 -> 3.4563015 | L38: =$L$1/1.1 -> 1.3636364 | M38: =D38+1.36 -> 7.7236364 | N38: =E38+1.5 -> 8.5 | O38: =M38-K38 -> 4.2673348 | P38: =100-Q38 -> 55.250333 | Q38: =K38/M38*100 -> 44.749667 | R38: =P38-G38 -> -3.0962052 | S38: =O38-F38 -> 0.55437329
A39: BURGER | B39: CALLEJERA | C39: =BURGERS!L64 -> 2.4731124 | D39: =BURGERS!L66 -> 9 | E39: =D39*1.1 -> 9.9 | F39: =D39-C39 -> 6.5268876 | G39: =100-H39 -> 72.520973 | H39: =C39/D39*100 -> 27.479027 | I39: 0.19187671 | J39: 0.61375 | K39: =I39+J39+C39 -> 3.2787391 | L39: =$L$1/1.1 -> 1.3636364 | M39: =D39+1.36 -> 10.36 | N39: =E39+1.5 -> 11.4 | O39: =M39-K39 -> 7.0812609 | P39: =100-Q39 -> 68.351939 | Q39: =K39/M39*100 -> 31.648061 | R39: =P39-G39 -> -4.1690342 | S39: =O39-F39 -> 0.55437329
A41: HOTDOG | B41: HOTDOG/ PERRITOS SIMPLE | C41: ='BRIOCH-SUBS'!L205 -> 1.7600676 | D41: ='BRIOCH-SUBS'!L207 -> 3.5454545 | E41: ='BRIOCH-SUBS'!L206 -> 3.9 | F41: =D41-C41 -> 1.785387 | G41: =100-H41 -> 50.357069 | H41: =C41/D41*100 -> 49.642931 | I41: 0.19187671 | J41: 0.61375 | K41: =I41+J41+C41 -> 2.5656943 | L41: =$L$1/1.1 -> 1.3636364 | M41: =D41+1.36 -> 4.9054545 | N41: =E41+1.5 -> 5.4 | O41: =M41-K41 -> 2.3397603 | P41: =100-Q41 -> 47.697114 | Q41: =K41/M41*100 -> 52.302886 | R41: =P41-G41 -> -2.6599542 | S41: =O41-F41 -> 0.55437329
A42: HOTDOG | B42: HOTDOG BACONQUESO | C42: ='BRIOCH-SUBS'!L223 -> 2.0661296 | D42: ='BRIOCH-SUBS'!L225 -> 5.3636364 | E42: ='BRIOCH-SUBS'!L224 -> 5.9 | F42: =D42-C42 -> 3.2975068 | G42: =100-H42 -> 61.47894 | H42: =C42/D42*100 -> 38.52106 | I42: 0.19187671 | J42: 0.61375 | K42: =I42+J42+C42 -> 2.8717563 | L42: =$L$1/1.1 -> 1.3636364 | M42: =D42+1.36 -> 6.7236364 | N42: =E42+1.5 -> 7.4 | O42: =M42-K42 -> 3.8518801 | P42: =100-Q42 -> 57.288644 | Q42: =K42/M42*100 -> 42.711356 | R42: =P42-G42 -> -4.1902965 | S42: =O42-F42 -> 0.55437329
A43: HOTDOG | B43: HOTDOG CHILL BBQ | C43: ='BRIOCH-SUBS'!L241 -> 1.8283224 | D43: ='BRIOCH-SUBS'!L243 -> 6.3636364 | E43: ='BRIOCH-SUBS'!L242 -> 7 | F43: =D43-C43 -> 4.535314 | G43: =100-H43 -> 71.269219 | H43: =C43/D43*100 -> 28.730781 | I43: 0.19187671 | J43: 0.61375 | K43: =I43+J43+C43 -> 2.6339491 | L43: =$L$1/1.1 -> 1.3636364 | M43: =D43+1.36 -> 7.7236364 | N43: =E43+1.5 -> 8.5 | O43: =M43-K43 -> 5.0896873 | P43: =100-Q43 -> 65.897552 | Q43: =K43/M43*100 -> 34.102449 | R43: =P43-G43 -> -5.3716679 | S43: =O43-F43 -> 0.55437329
A45: ENTRANTES | B45: BOX ALITAS | C45: =ENTRANTES!L34 -> 2.4242067 | D45: =ENTRANTES!L36 -> 5.4545455 | E45: =D45*1.1 -> 6 | F45: =D45-C45 -> 3.0303387 | G45: =100-H45 -> 55.55621 | H45: =C45/D45*100 -> 44.44379
A46: ENTRANTES | B46: BOX LAGRIMITAS | C46: =ENTRANTES!L90 -> 1.5589067 | D46: =ENTRANTES!L92 -> 5.4545455 | E46: =D46*1.1 -> 6 | F46: =D46-C46 -> 3.8956387 | G46: =100-H46 -> 71.420044 | H46: =C46/D46*100 -> 28.579956
...

Sheet SCRIPTS VENTAS Y MENU
B3: SUGERIR
B4: SIMPLE ASADO | C4: 26.814056
B5: SIMPLE EMPANADO | C5: 29.509
B6: SIMPLE SOLOMILO | C6: 28.035
B7: VEGETAL POLLO ASADO | C7: 23.169432
B8: VEGETAL EMPANADO | C8: 28.9018
B9: VEGETAL ATUN | C9: 29.2318
B10: CRISTIAN | C10: 23.946186
B11: JAKINIÑO | C11: 25.011913
B12: GUARRITO | C12: 23.738757
B15: SERRANO EMPANADO | C15: 26.512
B16: SERRANO POLLO | C16: 29.8305
B17: SERRANO POLLO ASADO | C17: 26.501586
... B49: TARRO RANCHERA | C49: 25.503333

Sheet UBER- RESUMEN DE COSTES
I1: =SUM(I3:I59) -> 464
A2: Familia | B2: Producto | C2: Coste € | D2: PVP sin IVA | E2: PVP Actual | F2: MARGEN POS UBER € | G2: MARGEN % | H2: Coste % | I2: Unidades Vendidas | J2: Peso venta %
A3: Bocadillos | B3: =BOCATAS!D2 -> SIMPLE DE POLLO | C3: =BOCATAS!L6 -> 1.4018182 | D3: =BOCATAS!L8 -> 3.6363636 | E3: =D3*1.1 -> 4 | F3: =D3-C3 -> 2.2345455 | G3: =BOCATAS!L11 -> 61.45 | H3: =BOCATAS!L10 -> 38.55 | I3: 163 | J3: =I3/SUM($I$3:I201)*100 -> 35.12931
A4: Bocadillos | B4: SIMPLE ASADO | C4: =BOCATAS!L34 -> 1.3407028 | D4: =BOCATAS!L36 -> 5 | E4: =D4*1.1 -> 5.5 | F4: =D4-C4 -> 3.6592972 | G4: =100-H4 -> 73.185944 | H4: =C4/D4*100 -> 26.814056 | I4: 33 | J4: =I4/SUM($I$3:I202)*100 -> 7.112069
A5: Bocadillos | B5: SIMPLE EMPANADO | C5: =BOCATAS!L20 -> 1.3413182 | D5: =BOCATAS!L22 -> 4.5454545 | E5: =D5*1.1 -> 5 | F5: =D5-C5 -> 3.2041364 | G5: =100-H5 -> 70.491 | H5: =C5/D5*100 -> 29.509 | I5: 31 | J5: =I5/SUM($I$3:I203)*100 -> 6.6810345
A6: Bocadillos | B6: SIMPLE SOLOMILO | C6: =BOCATAS!L48 -> 1.2743182 | D6: =BOCATAS!L50 -> 4.5454545 | E6: =D6*1.1 -> 5 | F6: =D6-C6 -> 3.2711364 | G6: =100-H6 -> 71.965 | H6: =C6/D6*100 -> 28.035 | I6: 19 | J6: =I6/SUM($I$3:I204)*100 -> 4.0948276
A7: Bocadillos | B7: VEGETAL POLLO | C7: =BOCATAS!L63 -> 1.3687182 | D7: =BOCATAS!P97 -> 6.2727273 | E7: =D7*1.1 -> 6.9 | F7: =D7-C7 -> 4.9040091 | G7: =100-H7 -> 78.179855 | H7: =C7/D7*100 -> 21.820145 | I7: 218 | J7: =I7/SUM($I$3:I205)*100 -> 46.982759
A8: Bocadillos | B8: VEGETAL POLLO ASADO | C8: =BOCATAS!L95 -> 1.3691028 | D8: =BOCATAS!P97 -> 6.2727273 | E8: =D8*1.1 -> 6.9 | F8: =D8-C8-(E8*0.2) -> 3.5236245 | G8: =F8/D8*100 -> 56.173724 | H8: =100-G8 -> 43.826276 | J8: =I8/SUM($I$3:I206)*100 -> 0
A9: Bocadillos | B9: VEGETAL EMPANADO | C9: =BOCATAS!L113 -> 1.3137182 | D9: =BOCATAS!P115 -> 6.3636364 | E9: =D9*1.1 -> 7 | F9: =D9-C9-(E9*0.2) -> 3.6499182 | G9: =F9/D9*100 -> 57.355857 | H9: =100-G9 -> 42.644143 | J9: =I9/SUM($I$3:I207)*100 -> 0
A10: Bocadillos | B10: VEGETAL ATUN | C10: =BOCATAS!L79 -> 1.3287182 | D10: =BOCATAS!L81 -> 4.5454545 | E10: =D10*1.1 -> 5 | F10: =D10-C10 -> 3.2167364 | G10: =100-H10 -> 70.7682 | H10: =C10/D10*100 -> 29.2318 | J10: =I10/SUM($I$3:I208)*100 -> 0
A11: Bocadillos | B11: BARBARA | C11: =BOCATAS!L131 -> 1.7153182 | D11: =BOCATAS!L133 -> 4.5454545 | E11: =D11*1.1 -> 5 | F11: =D11-C11 -> 2.8301364 | G11: =100-H11 -> 62.263 | H11: =C11/D11*100 -> 37.737 | J11: =I11/SUM($I$3:I209)*100 -> 0
A12: Bocadillos | B12: CRISTIAN | C12: =BOCATAS!L147 -> 1.5238482 | D12: =BOCATAS!L149 -> 6.3636364 | E12: =D12*1.1 -> 7 | F12: =D12-C12 -> 4.8397882 | G12: =100-H12 -> 76.053814 | H12: =C12/D12*100 -> 23.946186 | J12: =I12/SUM($I$3:I210)*100 -> 0
A13: Bocadillos | B13: JAKINIÑO | C13: =BOCATAS!L185 -> 1.8190482 | D13: =BOCATAS!P187 -> 8.1818182 | E13: =D13*1.1 -> 9 | F13: =D13-C13-(E13*0.2) -> 4.56277 | G13: =F13/D13*100 -> 55.767189 | H13: =100-G13 -> 44.232811 | J13: =I13/SUM($I$3:I211)*100 -> 0
A14: Bocadillos | B14: GUARRITO | C14: =BOCATAS!L166 -> 1.5106482 | D14: =BOCATAS!P168 -> 8.0909091 | E14: =D14*1.1 -> 8.9 | F14: =D14-C14-(E14*0.2) -> 4.8002609 | G14: =F14/D14*100 -> 59.329067 | H14: =100-G14 -> 40.670933 | J14: =I14/SUM($I$3:I212)*100 -> 0
A16: SERRANITOS | B16: SERRANO EMPANADO | C16: =SERRANOS!L34 -> 1.5666182 | D16: =SERRANOS!P36 -> 8.3636364 | E16: =D16*1.1 -> 9.2 | F16: =D16-C16-(E16*0.2) -> 4.9570182 | G16: =F16/D16*100 -> 59.268696 | H16: =100-G16 -> 40.731304 | J16: =I16/SUM($I$3:I214)*100 -> 0
A17: SERRANITOS | B17: SERRANO POLLO | C17: =SERRANOS!L6 -> 1.6271182 | D17: =SERRANOS!P8 -> 7.4545455 | E17: =D17*1.1 -> 8.2 | F17: =D17-C17-(E17*0.2) -> 4.1874273 | G17: =F17/D17*100 -> 56.172805 | H17: =100-G17 -> 43.827195 | J17: =I17/SUM($I$3:I215)*100 -> 0
A18: SERRANITOS | B18: SERRANO POLLO ASADO | C18: =SERRANOS!L63 -> 1.5660028 | D18: =SERRANOS!P65 -> 8.3636364 | E18: =D18*1.1 -> 9.2 | F18: =D18-C18-(E18*0.2) -> 4.9576336 | G18: =F18/D18*100 -> 59.276054 | H18: =100-G18 -> 40.723946 | J18: =I18/SUM($I$3:I216)*100 -> 0
A19: SERRANITOS | B19: SERRANO SOLOMILLO | C19: =SERRANOS!L92 -> 1.4996182 | D19: =SERRANOS!P94 -> 8.3636364 | E19: =D19*1.1 -> 9.2 | F19: =D19-C19-(E19*0.2) -> 5.0240182 | G19: =F19/D19*100 -> 60.069783 | H19: =100-G19 -> 39.930217 | J19: =I19/SUM($I$3:I217)*100 -> 0
A20: SERRANITOS | B20: SERRANO PULLED PORK | C20: =SERRANOS!L121 -> 1.7827765 | D20: =SERRANOS!P123 -> 8.3636364 | E20: =D20*1.1 -> 9.2 | F20: =D20-C20-(E20*0.2) -> 4.7408598 | G20: =F20/D20*100 -> 56.684194 | H20: =100-G20 -> 43.315806 | J20: =I20/SUM($I$3:I218)*100 -> 0
A22: BRIOCHES | B22: XMAS CHIKEN | C22: ='BRIOCH-SUBS'!L177 -> 2.0977582 | D22: ='BRIOCH-SUBS'!L179 -> 9 | E22: =D22*1.1 -> 9.9 | F22: =D22-C22-(E22*0.2) -> 4.9222418 | G22: =F22/D22*100 -> 54.691575 | H22: =100-G22 -> 45.308425 | K22: TEMPORADA
A23: BRIOCHES | B23: CESAR BRIOCHE | C23: ='BRIOCH-SUBS'!L149 -> 1.98895 | D23: ='BRIOCH-SUBS'!L159 -> 9 | E23: =D23*1.1 -> 9.9 | F23: =D23-C23-(E23*0.2) -> 5.03105 | G23: =F23/D23*100 -> 55.900556 | H23: =100-G23 -> 44.099444 | J23: =I23/SUM($I$3:I221)*100 -> 0
A24: BRIOCHES | B24: GYPSY | C24: ='BRIOCH-SUBS'!L64 -> 1.9596667 | D24: ='BRIOCH-SUBS'!L74 -> 9 | E24: =D24*1.1 -> 9.9 | F24: =D24-C24-(E24*0.2) -> 5.0603333 | G24: =F24/D24*100 -> 56.225926 | H24: =100-G24 -> 43.774074 | J24: =I24/SUM($I$3:I222)*100 -> 0
A25: BRIOCHES | B25: CHICKEN FRIED | C25: ='BRIOCH-SUBS'!L6 -> 1.9732002 | D25: ='BRIOCH-SUBS'!L16 -> 7.7272727 | E25: =D25*1.1 -> 8.5 | F25: =D25-C25-(E25*0.2) -> 4.0540726 | G25: =F25/D25*100 -> 52.464468 | H25: =100-G25 -> 47.535532 | J25: =I25/SUM($I$3:I223)*100 -> 0
A26: BRIOCHES | B26: CHEESE STEAK | C26: ='BRIOCH-SUBS'!L35 -> 2.3676979 | D26: ='BRIOCH-SUBS'!L37 -> 7.2727273 | E26: =D26*1.1 -> 8 | F26: =D26-C26-(E26*0.2) -> 3.3050294 | G26: =F26/D26*100 -> 45.444154 | H26: =100-G26 -> 54.555846 | J26: =I26/SUM($I$3:I224)*100 -> 0 | K26: PROXIMAMENTE
A27: BRIOCHES | B27: SMASH SERRANO | C27: ='BRIOCH-SUBS'!L93 -> 1.9800455 | D27: ='BRIOCH-SUBS'!L103 -> 10.818182 | E27: =D27*1.1 -> 11.9 | F27: =D27-C27-(E27*0.2) -> 6.4581364 | G27: =F27/D27*100 -> 59.697059 | H27: =100-G27 -> 40.302941 | J27: =I27/SUM($I$3:I225)*100 -> 0
A30: BURGER | B30: CRUJIPOLLO BBQ | C30: =BURGERS!L239 -> 1.8604959 | D30: =BURGERS!L249 -> 9.9090909 | E30: =D30*1.1 -> 10.9 | F30: =D30-C30-(E30*0.2) -> 5.868595 | G30: =F30/D30*100 -> 59.224354 | H30: =100-G30 -> 40.775646 | J30: =I30/SUM($I$3:I228)*100 -> 0
A31: BURGER | B31: CRUJIPOLLO ORIGINAL | C31: =BURGERS!L269 -> 1.5300542 | D31: =BURGERS!L279 -> 8.0909091 | E31: =D31*1.1 -> 8.9 | F31: =D31-C31-(E31*0.2) -> 4.7808549 | G31: =F31/D31*100 -> 59.089218 | H31: =100-G31 -> 40.910782 | J31: =I31/SUM($I$3:I229)*100 -> 0
A32: BURGER | B32: MAKA | C32: =BURGERS!L151 -> 2.2052973 | D32: =BURGERS!L161 -> 11.818182 | E32: =D32*1.1 -> 13 | F32: =D32-C32-(E32*0.2) -> 7.0128845 | G32: =F32/D32*100 -> 59.339792 | H32: =100-G32 -> 40.660208 | J32: =I32/SUM($I$3:I230)*100 -> 0
A33: BURGER | B33: BICHOTA | C33: =BURGERS!L180 -> 2.1501303 | D33: =BURGERS!L190 -> 11.818182 | E33: =D33*1.1 -> 13 | F33: =D33-C33-(E33*0.2) -> 7.0680515 | G33: =F33/D33*100 -> 59.80659 | H33: =100-G33 -> 40.19341 | J33: =I33/SUM($I$3:I231)*100 -> 0
A34: BURGER | B34: DADDY | C34: =BURGERS!L209 -> 2.5895738 | E34: =D34*1.1 -> 0 | F34: =D34-C34-(E34*0.2) -> -2.5895738 | G34: =F34/D34*100 -> #DIV/0! | H34: =100-G34 -> #DIV/0! | J34: =I34/SUM($I$3:I232)*100 -> 0 | K34: RETIRADO
A35: BURGER | B35: DOBLE QUESOS | C35: =BURGERS!L6 -> 2.1871023 | D35: =BURGERS!L16 -> 10.818182 | E35: =D35*1.1 -> 11.9 | F35: =D35-C35-(E35*0.2) -> 6.2510795 | G35: =F35/D35*100 -> 57.783088 | H35: =100-G35 -> 42.216912 | J35: =I35/SUM($I$3:I233)*100 -> 0
A36: BURGER | B36: CERO15 | C36: =BURGERS!L35 -> 2.3754736 | D36: =BURGERS!L45 -> 10.818182 | E36: =D36*1.1 -> 11.9 | F36: =D36-C36-(E36*0.2) -> 6.0627082 | G36: =F36/D36*100 -> 56.041841 | H36: =100-G36 -> 43.958159 | J36: =I36/SUM($I$3:I234)*100 -> 0
A37: BURGER | B37: KAROL | C37: =BURGERS!L122 -> 2.5701467 | D37: =BURGERS!L132 -> 9.9090909 | E37: =D37*1.1 -> 10.9 | F37: =D37-C37-(E37*0.2) -> 5.1589442 | G37: =F37/D37*100 -> 52.062739 | H37: =100-G37 -> 47.937261 | J37: =I37/SUM($I$3:I235)*100 -> 0 | K37: RETIRADO
A38: BURGER | B38: BARRIERA | C38: =BURGERS!L93 -> 2.6506748 | D38: =BURGERS!L103 -> 9 | E38: =D38*1.1 -> 9.9 | F38: =D38-C38-(E38*0.2) -> 4.3693252 | G38: =F38/D38*100 -> 48.548058 | H38: =100-G38 -> 51.451942 | J38: =I38/SUM($I$3:I236)*100 -> 0
A39: BURGER | B39: CALLEJERA | C39: =BURGERS!L64 -> 2.4731124 | D39: =BURGERS!L74 -> 10.818182 | E39: =D39*1.1 -> 11.9 | F39: =D39-C39-(E39*0.2) -> 5.9650694 | G39: =F39/D39*100 -> 55.139297 | H39: =100-G39 -> 44.860703 | J39: =I39/SUM($I$3:I237)*100 -> 0 | K39: NUEVA
A41: ENTRANTES | B41: BOX ALITAS | C41: =ENTRANTES!L34 -> 2.4242067 | D41: =ENTRANTES!L44 -> 6.3636364 | E41: =D41*1.1 -> 7 | F41: =D41-C41-(E41*0.2) -> 2.5394297 | G41: =F41/D41*100 -> 39.905323 | H41: =100-G41 -> 60.094677 | J41: =I41/SUM($I$3:I239)*100 -> 0 | K41: RETIRADO
A42: ENTRANTES | B42: BOX LAGRIMITAS | C42: =ENTRANTES!L90 -> 1.5589067 | D42: =ENTRANTES!L100 -> 6.3636364 | E42: =D42*1.1 -> 7 | F42: =D42-C42-(E42*0.2) -> 3.4047297 | G42: =F42/D42*100 -> 53.502895 | H42: =100-G42 -> 46.497105 | J42: =I42/SUM($I$3:I240)*100 -> 0
A43: ENTRANTES | B43: BOX NUGGETS | C43: =ENTRANTES!L6 -> 1.8325067 | D43: =ENTRANTES!L16 -> 7.0909091 | E43: =D43*1.1 -> 7.8 | F43: =D43-C43-(E43*0.2) -> 3.6984024 | G43: =F43/D43*100 -> 52.156957 | H43: =100-G43 -> 47.843043 | J43: =I43/SUM($I$3:I241)*100 -> 0
A44: ENTRANTES | B44: BOX PATATAS | C44: =ENTRANTES!L118 -> 0.91663342 | D44: =ENTRANTES!L128 -> 5.9090909 | E44: =D44*1.1 -> 6.5 | F44: =D44-C44-(E44*0.2) -> 3.6924575 | G44: =F44/D44*100 -> 62.487742 | H44: =100-G44 -> 37.512258 | J44: =I44/SUM($I$3:I242)*100 -> 0
A45: ENTRANTES | B45: BOX PAPAS PULLED PORK | C45: =ENTRANTES!L174 -> 1.3761221 | D45: =ENTRANTES!L184 -> 6.8181818 | E45: =D45*1.1 -> 7.5 | F45: =D45-C45-(E45*0.2) -> 3.9420597 | G45: =F45/D45*100 -> 57.816876 | H45: =100-G45 -> 42.183124 | J45: =I45/SUM($I$3:I243)*100 -> 0
...

Sheet MENUS
C2: PRODUCTO | D2: MENU SERRANO DE POLLO+LATA+TARRO
B5: ID | C5: Nombre del Plato | D5: Unidad de medida | E5: Precio Unidad | F5: Cantidad Bruta | G5: Cantidad Cocinada/limpia | H5: Merma % | I5: Coste | K5: INDICE | O5: INDICE UBER
B6: {=+XLOOKUP(C6,'Base de datos'!C:C,'Base de datos'!A:A,"",FALSE)} | D6: Kg | E6: {=+XLOOKUP(B6,'Base de datos'!A:A,'Base de datos'!H:H,0)} -> 0 | H6: =IFERROR(1-G6/F6,"") | I6: =IFERROR(E6*F6,"") -> 0 | K6: Coste Total | L6: =SUM(I6:I19) -> 2.4327449 | O6: Coste Total | P6: =L6 -> 2.4327449
B7: =K31 -> PVP | C7: =C31 | D7: Kg | H7: =IFERROR(1-G7/F7,"") | I7: =IFERROR(E7*F7,"") -> 0 | K7: PVP | L7: 8 | O7: PVP | P7: 8.2
B8: {=+XLOOKUP(C8,'Base de datos'!C:C,'Base de datos'!A:A,"",FALSE)} -> 63 | C8: PECHUGA POLLO FILETEADA 25 SADA | D8: Kg | E8: {=+XLOOKUP(B8,'Base de datos'!A:A,'Base de datos'!H:H,0)} -> 6.15 | F8: 0.11 | G8: 0.1 | H8: =IFERROR(1-G8/F8,"") -> 0.090909091 | I8: =IFERROR(E8*F8,"") -> 0.6765 | K8: Precio venta (s/IVA) | L8: =L7/1.1 -> 7.2727273 | O8: Precio venta (s/IVA) | P8: =P7/1.1 -> 7.4545455
B9: {=+XLOOKUP(C9,'Base de datos'!C:C,'Base de datos'!A:A,"",FALSE)} -> 110 | C9: PAN BAGUETTE LA PARRA | D9: Unidad | E9: {=+XLOOKUP(B9,'Base de datos'!A:A,'Base de datos'!H:H,0)} -> 0.28181818 | F9: 1 | G9: 1 | H9: =IFERROR(1-G9/F9,"") -> 0 | I9: =IFERROR(E9*F9,"") -> 0.28181818 | K9: IVA | L9: 0.1 | O9: IVA | P9: 0.1
B10: {=+XLOOKUP(C10,'Base de datos'!C:C,'Base de datos'!A:A,"",FALSE)} -> 96 | C10: TOMATE DANIELA | D10: Kg | E10: {=+XLOOKUP(B10,'Base de datos'!A:A,'Base de datos'!H:H,0)} -> 1.8 | F10: 0.01 | G10: 0.01 | H10: =IFERROR(1-G10/F10,"") -> 0 | I10: =IFERROR(E10*F10,"") -> 0.018 | K10: Coste de Producto | L10: =L6/L8*100 -> 33.450242 | M10: % | O10: Coste de Producto | P10: =P6/P8*100 -> 32.634383 | Q10: %
B11: {=+XLOOKUP(C11,'Base de datos'!C:C,'Base de datos'!A:A,"",FALSE)} -> 72 | C11: PIMIENTO | D11: Kg | E11: {=+XLOOKUP(B11,'Base de datos'!A:A,'Base de datos'!H:H,0)} -> 2 | F11: 0.01 | G11: 0.01 | H11: =IFERROR(1-G11/F11,"") -> 0 | I11: =IFERROR(E11*F11,"") -> 0.02 | K11: Margen Bruto | L11: =100-L10 -> 66.549758 | M11: % | O11: Margen Bruto | P11: =P8-P6 -> 5.0218006 | Q11: €
B12: {=+XLOOKUP(C12,'Base de datos'!C:C,'Base de datos'!A:A,"",FALSE)} -> 37 | C12: JAMON LONCHEADO CUMBRE IB. | D12: Kg | E12: {=+XLOOKUP(B12,'Base de datos'!A:A,'Base de datos'!H:H,0)} -> 7 | F12: 0.02 | G12: 0.02 | H12: =IFERROR(1-G12/F12,"") -> 0 | I12: =IFERROR(E12*F12,"") -> 0.14 | O12: Margen Bruto post Uber | P12: =P8-P6-(P7*0.2) -> 3.3818006 | Q12: €
B13: {=+XLOOKUP(C13,'Base de datos'!C:C,'Base de datos'!A:A,"",FALSE)} -> 34 | C13: HUEVO LÍQUIDO GRANJA | D13: Litro | E13: {=+XLOOKUP(B13,'Base de datos'!A:A,'Base de datos'!H:H,0)} -> 3.75 | F13: 0.02 | G13: 0.02 | H13: =IFERROR(1-G13/F13,"") -> 0 | I13: =IFERROR(E13*F13,"") -> 0.075 | K13: SERRANO POLLO | L13: 6 | O13: Margen Bruto post Uber | P13: =P12/P8 -> 0.45365617 | Q13: %
B14: {=+XLOOKUP(C14,'Base de datos'!C:C,'Base de datos'!A:A,"",FALSE)} | D14: Kg | E14: {=+XLOOKUP(B14,'Base de datos'!A:A,'Base de datos'!H:H,0)} -> 0 | I14: =IFERROR(E14*F14,"") -> 0 | K14: TARRO ALIOLI | L14: 0.5
B15: {=+XLOOKUP(C15,'Base de datos'!C:C,'Base de datos'!A:A,"",FALSE)} -> 93 | C15: SERVILLETA 40X40 100UD | D15: Unidad | E15: {=+XLOOKUP(B15,'Base de datos'!A:A,'Base de datos'!H:H,0)} -> 0.0277 | F15: 1 | G15: 1 | H15: =IFERROR(1-G15/F15,"") -> 0 | I15: =IFERROR(E15*F15,"") -> 0.0277 | K15: BEBIDA COCACOLA | L15: 1.5
B16: {=+XLOOKUP(C16,'Base de datos'!C:C,'Base de datos'!A:A,"",FALSE)} -> 29 | C16: ENVASE SERRANO IP10 .25 | D16: Unidad | E16: {=+XLOOKUP(B16,'Base de datos'!A:A,'Base de datos'!H:H,0)} -> 0.1946 | F16: 1 | G16: 1 | H16: =IFERROR(1-G16/F16,"") -> 0 | I16: =IFERROR(E16*F16,"") -> 0.1946 | K16: TOTAL | L16: =SUM(L13:L15) -> 8
B17: {=+XLOOKUP(C17,'Base de datos'!C:C,'Base de datos'!A:A,"",FALSE)} -> 58 | C17: PATATAS FRY & DIP 25 | D17: Kg | E17: {=+XLOOKUP(B17,'Base de datos'!A:A,'Base de datos'!H:H,0)} -> 2.15 | F17: 0.09 | H17: =IFERROR(1-G17/F17,"") -> 1 | I17: =IFERROR(E17*F17,"") -> 0.1935
B18: {=+XLOOKUP(C18,'Base de datos'!C:C,'Base de datos'!A:A,"",FALSE)} -> 103 | C18: LATA COCACOLA | D18: Kg | E18: {=+XLOOKUP(B18,'Base de datos'!A:A,'Base de datos'!H:H,0)} -> 0.61375 | F18: 1 | H18: =IFERROR(1-G18/F18,"") -> 1 | I18: =IFERROR(E18*F18,"") -> 0.61375
B19: {=+XLOOKUP(C19,'Base de datos'!C:C,'Base de datos'!A:A,"",FALSE)} -> 166 | C19: TARRITO ALIOLI | D19: Kg | E19: {=+XLOOKUP(B19,'Base de datos'!A:A,'Base de datos'!H:H,0)} -> 0.19187671 | F19: 1 | H19: =IFERROR(1-G19/F19,"") -> 1 | I19: =IFERROR(E19*F19,"") -> 0.19187671
C21: Notas de elaboración
B30: {=+XLOOKUP(C30,'Base de datos'!C:C,'Base de datos'!A:A,"",FALSE)} | D30: Kg | E30: {=+XLOOKUP(B30,'Base de datos'!A:A,'Base de datos'!H:H,0)} -> 0 | H30: =IFERROR(1-G30/F30,"") | I30: =IFERROR(E30*F30,"") -> 0 | K30: Coste Total | L30: =SUM(I30:I35) -> 4.3
B31: =K49 | C31: =C49 | D31: Kg | E31: =K55 -> IVA | H31: =IFERROR(1-G31/F31,"") | I31: =IFERROR(E31*F31,"") | K31: PVP | L31: 6.5
B32: {=+XLOOKUP(C32,'Base de datos'!C:C,'Base de datos'!A:A,"",FALSE)} -> 97 | C32: TARTAS DUBAI | D32: Kg | E32: {=+XLOOKUP(B32,'Base de datos'!A:A,'Base de datos'!H:H,0)} -> 4.3 | F32: 1 | G32: 1 | H32: =IFERROR(1-G32/F32,"") -> 0 | I32: =IFERROR(E32*F32,"") -> 4.3 | K32: Precio venta (s/IVA) | L32: =L31/1.1 -> 5.9090909
B33: {=+XLOOKUP(C33,'Base de datos'!C:C,'Base de datos'!A:A,"",FALSE)} | D33: Unidad | E33: {=+XLOOKUP(B33,'Base de datos'!A:A,'Base de datos'!H:H,0)} -> 0 | I33: =IFERROR(E33*F33,"") -> 0 | K33: IVA | L33: 0.1
B34: {=+XLOOKUP(C34,'Base de datos'!C:C,'Base de datos'!A:A,"",FALSE)} | D34: Kg | E34: {=+XLOOKUP(B34,'Base de datos'!A:A,'Base de datos'!H:H,0)} -> 0 | I34: =IFERROR(E34*F34,"") -> 0 | K34: Coste de Producto | L34: =L30/L32*100 -> 72.769231 | M34: %
B35: {=+XLOOKUP(C35,'Base de datos'!C:C,'Base de datos'!A:A,"",FALSE)} | D35: Unidad | E35: {=+XLOOKUP(B35,'Base de datos'!A:A,'Base de datos'!H:H,0)} -> 0 | I35: =IFERROR(E35*F35,"") -> 0 | K35: Margen Bruto | L35: =100-L34 -> 27.230769 | M35: %
C37: Notas de elaboración 1 | K37: INDICE UBER
K38: Coste Total | L38: =L30 -> 4.3
K39: PVP | L39: 8
C40: DESCATALOGADA | K40: Precio venta (s/IVA) | L40: =L39/1.1 -> 7.2727273
K41: IVA | L41: 0.1
K42: Coste de Producto | L42: =L38/L40*100 -> 59.125 | M42: %
K43: Margen Bruto | L43: =L40-L38 -> 2.9727273 | M43: €
K44: Margen Bruto post Uber | L44: =L40-L38-(L39*0.2) -> 1.3727273 | M44: €
K45: Margen Bruto post Uber | L45: =L44/L40 -> 0.18875 | M45: %
C48: PRODUCTO | D48: TARTA LOTUS | K48: IR A BASE DE DATOS
B51: ID | C51: Nombre del Plato | D51: Unidad de medida | E51: Precio Unidad | F51: Cantidad Bruta | G51: Cantidad Cocinada/limpia | H51: Merma % | I51: Coste | K51: INDICE
B52: {=+XLOOKUP(C52,'Base de datos'!C:C,'Base de datos'!A:A,"",FALSE)} | D52: Kg | E52: {=+XLOOKUP(B52,'Base de datos'!A:A,'Base de datos'!H:H,0)} -> 0 | H52: =IFERROR(1-G52/F52,"") | I52: =IFERROR(E52*F52,"") -> 0 | K52: Coste Total | L52: =SUM(I52:I57) -> 1.43
B53: =K69 | C53: =C69 | D53: Kg | E53: =K75 | H53: =IFERROR(1-G53/F53,"") | I53: =IFERROR(E53*F53,"") -> 0 | K53: PVP | L53: 6
B54: {=+XLOOKUP(C54,'Base de datos'!C:C,'Base de datos'!A:A,"",FALSE)} -> 92 | C54: TARTA LOTUS | D54: Kg | E54: {=+XLOOKUP(B54,'Base de datos'!A:A,'Base de datos'!H:H,0)} -> 1.43 | F54: 1 | G54: 1 | H54: =IFERROR(1-G54/F54,"") -> 0 | I54: =IFERROR(E54*F54,"") -> 1.43 | K54: Precio venta (s/IVA) | L54: =L53/1.1 -> 5.4545455
B55: {=+XLOOKUP(C55,'Base de datos'!C:C,'Base de datos'!A:A,"",FALSE)} | D55: Unidad | E55: {=+XLOOKUP(B55,'Base de datos'!A:A,'Base de datos'!H:H,0)} -> 0 | I55: =IFERROR(E55*F55,"") -> 0 | K55: IVA | L55: 0.1
B56: {=+XLOOKUP(C56,'Base de datos'!C:C,'Base de datos'!A:A,"",FALSE)} | D56: Kg | E56: {=+XLOOKUP(B56,'Base de datos'!A:A,'Base de datos'!H:H,0)} -> 0 | I56: =IFERROR(E56*F56,"") -> 0 | K56: Coste de Producto | L56: =L52/L54*100 -> 26.216667 | M56: %
B57: {=+XLOOKUP(C57,'Base de datos'!C:C,'Base de datos'!A:A,"",FALSE)} | D57: Unidad | E57: {=+XLOOKUP(B57,'Base de datos'!A:A,'Base de datos'!H:H,0)} -> 0 | I57: =IFERROR(E57*F57,"") -> 0 | K57: Margen Bruto | L57: =100-L56 -> 73.783333 | M57: %
...

Sheet TAREASNOTAS
B4: TAREAS
B5: VER ESCANDALLO HOTDOG
B6: MEDIA PONDERADA EN CELDA DE RESUMEN DE COSTE
B7: RAPPEL R2R APLICAO

Sheet VENTAS TOTALES
A1: Categoría | B1: Producto | C1: Unidades | D1: Total (€) | E1: ULTIMA ACTUALIZACION | G1: 46090
A2: Burgers | B2: Bichota Campeona 2023 Sevilla League | C2: 608 | D2: 6129
A3: Burgers | B3: Doblesquesos | C3: 634 | D3: 5293.5
A4: Serranitos | B4: Serranito Pollo | C4: 837 | D4: 5073
A5: Burgers | B5: Cero15 | C5: 450 | D5: 3677.2
A6: Burgers & MENU | B6: Dobles Quesos | C6: 282 | D6: 3324.8
A7: Burgers | B7: Barriera Cheese burger PM | C7: 386 | D7: 2968.4
A8: Burgers & MENU | B8: CAMPEONA SEVILLA BURGER LEAGUE “LA BICHOTA” | C8: 222 | D8: 2768.1
A9: SERRANITOS & BAGUETTES by SOFI | B9: SERRANITO de POLLO + patatas | C9: 316 | D9: 2712.1
A10: Burgers | B10: Sofi | C10: 312 | D10: 2628.7
A11: Bocatas | B11: Joaquinto | C11: 288 | D11: 2312.7
A12: Serranitos | B12: Serranito Pollo Asado | C12: 279 | D12: 1862.5
A13: Serranitos | B13: Serranito Solomillo | C13: 253 | D13: 1780.5
... A146: TARRO EXTRA | B146: TARRO KETCHUP EXTRA | C146: 1 | D146: 0.75

Sheet Bebidas
B2: Instrucciones: 1. Solo editar sobre las celdas en blanco y naranja 2. Si se pone aperitivo de cortesía con la bebida rellenar en la celda naranja (MEDIA del coste de aperitivos) 3. Meter IVA
B4: Coste aperitivo | C4: 0.1
B5: IVA | C5: 0.1
C7: Coste total | D7: Coste apertivo | E7: Coste bebida | F7: PVP con IVA | G7: PVP sin IVA | H7: Margen Bruto | I7: Coste de Producto%
B8: CERVEZAS
C9: =SUM($C$4+E9) -> 0.1 | G9: =F9/1.21 -> 0 | H9: =G9-C9 -> -0.1 | I9: =1-(H9/G9) -> #DIV/0!
C10: =SUM($C$4+E10) -> 0.1 | G10: =F10/1.21 -> 0 | H10: =G10-C10 -> -0.1 | I10: =1-(H10/G10) -> #DIV/0!
C11: 0.1 | G11: =F11/1.21 -> 0 | H11: =G11-C11 -> -0.1 | I11: =1-(H11/G11) -> #DIV/0!
C12: =SUM($C$4+E12) -> 0.1 | G12: =F12/1.21 -> 0 | H12: =G12-C12 -> -0.1 | I12: =1-(H12/G12) -> #DIV/0!
C13: =SUM($C$4+E13) -> 0.1 | G13: =F13/1.21 -> 0 | H13: =G13-C13 -> -0.1 | I13: =1-(H13/G13) -> #DIV/0!
C14: =SUM($C$4+E14) -> 0.1 | G14: =F14/1.21 -> 0 | H14: =G14-C14 -> -0.1 | I14: =1-(H14/G14) -> #DIV/0!
C15: =SUM($C$4+E15) -> 0.1 | G15: =F15/1.21 -> 0 | H15: =G15-C15 -> -0.1 | I15: =1-(H15/G15) -> #DIV/0!
C16: =SUM($C$4+E16) -> 0.1 | G16: =F16/1.21 -> 0 | H16: =G16-C16 -> -0.1 | I16: =1-(H16/G16) -> #DIV/0!
C17: =SUM($C$4+E17) -> 0.1 | G17: =F17/1.21 -> 0 | H17: =G17-C17 -> -0.1 | I17: =1-(H17/G17) -> #DIV/0!
C18: =SUM($C$4+E18) -> 0.1 | G18: =F18/1.21 -> 0 | H18: =G18-C18 -> -0.1 | I18: =1-(H18/G18) -> #DIV/0!
B19: REFRESCOS | C19: =SUM($C$4+E19) -> 0.1
B20: ='Base de datos'!C102 -> LATA AQUARIOUS LIMON | C20: =SUM($C$4+E20) -> 0.82791667 | E20: ='Base de datos'!H102 -> 0.72791667 | F20: 1.6 | G20: =F20/1.21 -> 1.322314 | H20: =G20-C20 -> 0.49439738 | I20: =1-(H20/G20) -> 0.62611198
B21: ='Base de datos'!C103 -> LATA AQUARIOUS NARANJA | C21: =SUM($C$4+E21) -> 0.82791667 | E21: ='Base de datos'!H103 -> 0.72791667 | F21: 1.6 | G21: =F21/1.21 -> 1.322314 | H21: =G21-C21 -> 0.49439738 | I21: =1-(H21/G21) -> 0.62611198
B22: ='Base de datos'!C104 -> LATA COCACOLA | C22: =SUM($C$4+E22) -> 0.71375 | E22: ='Base de datos'!H104 -> 0.61375 | F22: 1.5 | G22: =F22/1.21 -> 1.2396694 | H22: =G22-C22 -> 0.52591942 | I22: =1-(H22/G22) -> 0.57575833
B23: ='Base de datos'!C105 -> LATA COCACOLA ZERO | C23: =SUM($C$4+E23) -> 0.71375 | E23: ='Base de datos'!H105 -> 0.61375 | F23: 1.5 | G23: =F23/1.21 -> 1.2396694 | H23: =G23-C23 -> 0.52591942 | I23: =1-(H23/G23) -> 0.57575833
B24: ='Base de datos'!C106 -> LATA COLACOLA ZERO ZERO | C24: =SUM($C$4+E24) -> 0.71375 | E24: ='Base de datos'!H106 -> 0.61375 | F24: 1.5 | G24: =F24/1.21 -> 1.2396694 | H24: =G24-C24 -> 0.52591942 | I24: =1-(H24/G24) -> 0.57575833
B25: ='Base de datos'!C107 -> LATA FANTA LIMON | C25: =SUM($C$4+E25) -> 0.62666667 | E25: ='Base de datos'!H107 -> 0.52666667 | F25: 1.5 | G25: =F25/1.21 -> 1.2396694 | H25: =G25-C25 -> 0.61300275 | I25: =1-(H25/G25) -> 0.50551111
B26: ='Base de datos'!C108 -> LATA FANTA NARANJA | C26: =SUM($C$4+E26) -> 0.62666667 | E26: ='Base de datos'!H108 -> 0.52666667 | F26: 1.5 | G26: =F26/1.21 -> 1.2396694 | H26: =G26-C26 -> 0.61300275 | I26: =1-(H26/G26) -> 0.50551111
B27: ='Base de datos'!C109 -> LATA FUZEE TEA LIMON | C27: =SUM($C$4+E27) -> 0.735 | E27: ='Base de datos'!H109 -> 0.635 | F27: 1.6 | G27: =F27/1.21 -> 1.322314 | H27: =G27-C27 -> 0.58731405 | I27: =1-(H27/G27) -> 0.55584375
B28: ='Base de datos'!C110 -> LATA FUZEE TEA MARACUYA | C28: =SUM($C$4+E28) -> 0.735 | E28: ='Base de datos'!H110 -> 0.635 | F28: 1.6 | G28: =F28/1.21 -> 1.322314 | H28: =G28-C28 -> 0.58731405 | I28: =1-(H28/G28) -> 0.55584375
C29: =SUM($C$4+E29) -> 0.1 | G29: =F29/1.21 -> 0 | H29: =G29-C29 -> -0.1 | I29: =1-(H29/G29) -> #DIV/0!
C30: =SUM($C$4+E30) -> 0.1 | G30: =F30/1.1 -> 0 | H30: =G30-C30 -> -0.1 | I30: =1-(H30/G30) -> #DIV/0!
C31: =SUM($C$4+E31) -> 0.1 | G31: =F31/1.21 -> 0 | H31: =G31-C31 -> -0.1 | I31: =1-(H31/G31) -> #DIV/0!
C32: =SUM($C$4+E32) -> 0.1 | G32: =F32/1.21 -> 0 | H32: =G32-C32 -> -0.1 | I32: =1-(H32/G32) -> #DIV/0!
C33: =SUM($C$4+E33) -> 0.1 | G33: =F33/1.1 -> 0 | H33: =G33-C33 -> -0.1 | I33: =1-(H33/G33) -> #DIV/0!
B34: Copas de vino
C35: =SUM(E35) -> 0 | G35: =F35/1.21 -> 0 | H35: =G35-C35 -> 0 | I35: =1-(H35/G35) -> #DIV/0! | K35: AGUILA Y ORO APLICANDO UN 10% DE MERMA
